Workbook
Name Slicer_Beverage_Brand: #N/A
Name Slicer_Beverage_Brand1: #N/A
Name Slicer_Month_in_Words1: #N/A

Sheet Data
A1: Retailer | B1: Retailer ID | C1: Invoice Date | D1: Region | E1: State | F1: City | G1: Beverage Brand | H1: Price per Unit | I1: Formated Price Per Unit | J1: Units Sold | K1: Total Sales | L1: Operating Profit | M1: Operating Margin | N1: Year | O1: Month | P1: Month in Words
A2: Sodapop | B2: 1185732 | C2: 44210 | D2: Northeast | E2: New York | F2: New York | G2: Coca-Cola | H2: 0.5 | I2: =ROUND(Table1[[#This Row],[Price per Unit]],2) -> 0.5 | J2: 12000 | K2: =H2*J2 -> 6000 | L2: =K2*M2 -> 3000 | M2: 0.5 | N2: =YEAR(C2) -> 2021 | O2: =MONTH(C2) -> 1 | P2: =TEXT(DATE(Table1[[#This Row],[Year]],Table1[[#This Row],[Month]],1),"mmm") -> Jan
A3: Sodapop | B3: 1185732 | C3: 44210 | D3: Northeast | E3: New York | F3: New York | G3: Diet Coke | H3: 0.5 | I3: =ROUND(Table1[[#This Row],[Price per Unit]],2) -> 0.5 | J3: 10000 | K3: =H3*J3 -> 5000 | L3: =K3*M3 -> 1500 | M3: 0.3 | N3: =YEAR(C3) -> 2021 | O3: =MONTH(C3) -> 1 | P3: =TEXT(DATE(Table1[[#This Row],[Year]],Table1[[#This Row],[Month]],1),"mmm") -> Jan
A4: Sodapop | B4: 1185732 | C4: 44210 | D4: Northeast | E4: New York | F4: New York | G4: Sprite | H4: 0.4 | I4: =ROUND(Table1[[#This Row],[Price per Unit]],2) -> 0.4 | J4: 10000 | K4: =H4*J4 -> 4000 | L4: =K4*M4 -> 1400 | M4: 0.35 | N4: =YEAR(C4) -> 2021 | O4: =MONTH(C4) -> 1 | P4: =TEXT(DATE(Table1[[#This Row],[Year]],Table1[[#This Row],[Month]],1),"mmm") -> Jan
A5: Sodapop | B5: 1185732 | C5: 44210 | D5: Northeast | E5: New York | F5: New York | G5: Fanta | H5: 0.45 | I5: =ROUND(Table1[[#This Row],[Price per Unit]],2) -> 0.45 | J5: 8500 | K5: =H5*J5 -> 3825 | L5: =K5*M5 -> 1338.75 | M5: 0.35 | N5: =YEAR(C5) -> 2021 | O5: =MONTH(C5) -> 1 | P5: =TEXT(DATE(Table1[[#This Row],[Year]],Table1[[#This Row],[Month]],1),"mmm") -> Jan
A6: Sodapop | B6: 1185732 | C6: 44210 | D6: Northeast | E6: New York | F6: New York | G6: Powerade | H6: 0.6 | I6: =ROUND(Table1[[#This Row],[Price per Unit]],2) -> 0.6 | J6: 9000 | K6: =H6*J6 -> 5400 | L6: =K6*M6 -> 1620 | M6: 0.3 | N6: =YEAR(C6) -> 2021 | O6: =MONTH(C6) -> 1 | P6: =TEXT(DATE(Table1[[#This Row],[Year]],Table1[[#This Row],[Month]],1),"mmm") -> Jan | Y6: Metrics | Z6: This tells (HOW MUCH / HOW GOOD)
A7: Sodapop | B7: 1185732 | C7: 44210 | D7: Northeast | E7: New York | F7: New York | G7: Dasani Water | H7: 0.5 | I7: =ROUND(Table1[[#This Row],[Price per Unit]],2) -> 0.5 | J7: 10000 | K7: =H7*J7 -> 5000 | L7: =K7*M7 -> 1250 | M7: 0.25 | N7: =YEAR(C7) -> 2021 | O7: =MONTH(C7) -> 1 | P7: =TEXT(DATE(Table1[[#This Row],[Year]],Table1[[#This Row],[Month]],1),"mmm") -> Jan
A8: Sodapop | B8: 1185732 | C8: 44239 | D8: Northeast | E8: New York | F8: New York | G8: Coca-Cola | H8: 0.5 | I8: =ROUND(Table1[[#This Row],[Price per Unit]],2) -> 0.5 | J8: 12500 | K8: =H8*J8 -> 6250 | L8: =K8*M8 -> 3125 | M8: 0.5 | N8: =YEAR(C8) -> 2021 | O8: =MONTH(C8) -> 2 | P8: =TEXT(DATE(Table1[[#This Row],[Year]],Table1[[#This Row],[Month]],1),"mmm") -> Feb | Y8: Performance Measure
A9: Sodapop | B9: 1185732 | C9: 44239 | D9: Northeast | E9: New York | F9: New York | G9: Diet Coke | H9: 0.5 | I9: =ROUND(Table1[[#This Row],[Price per Unit]],2) -> 0.5 | J9: 9000 | K9: =H9*J9 -> 4500 | L9: =K9*M9 -> 1350 | M9: 0.3 | N9: =YEAR(C9) -> 2021 | O9: =MONTH(C9) -> 2 | P9: =TEXT(DATE(Table1[[#This Row],[Year]],Table1[[#This Row],[Month]],1),"mmm") -> Feb
A10: Sodapop | B10: 1185732 | C10: 44239 | D10: Northeast | E10: New York | F10: New York | G10: Sprite | H10: 0.4 | I10: =ROUND(Table1[[#This Row],[Price per Unit]],2) -> 0.4 | J10: 9500 | K10: =H10*J10 -> 3800 | L10: =K10*M10 -> 1330 | M10: 0.35 | N10: =YEAR(C10) -> 2021 | O10: =MONTH(C10) -> 2 | P10: =TEXT(DATE(Table1[[#This Row],[Year]],Table1[[#This Row],[Month]],1),"mmm") -> Feb | Y10: Price per Unit | Z10: pricing power
A11: Sodapop | B11: 1185732 | C11: 44239 | D11: Northeast | E11: New York | F11: New York | G11: Fanta | H11: 0.45 | I11: =ROUND(Table1[[#This Row],[Price per Unit]],2) -> 0.45 | J11: 8250 | K11: =H11*J11 -> 3712.5 | L11: =K11*M11 -> 1299.375 | M11: 0.35 | N11: =YEAR(C11) -> 2021 | O11: =MONTH(C11) -> 2 | P11: =TEXT(DATE(Table1[[#This Row],[Year]],Table1[[#This Row],[Month]],1),"mmm") -> Feb
A12: Sodapop | B12: 1185732 | C12: 44239 | D12: Northeast | E12: New York | F12: New York | G12: Powerade | H12: 0.6 | I12: =ROUND(Table1[[#This Row],[Price per Unit]],2) -> 0.6 | J12: 9000 | K12: =H12*J12 -> 5400 | L12: =K12*M12 -> 1620 | M12: 0.3 | N12: =YEAR(C12) -> 2021 | O12: =MONTH(C12) -> 2 | P12: =TEXT(DATE(Table1[[#This Row],[Year]],Table1[[#This Row],[Month]],1),"mmm") -> Feb | Y12: Units Sold | Z12: Volume
A13: Sodapop | B13: 1185732 | C13: 44239 | D13: Northeast | E13: New York | F13: New York | G13: Dasani Water | H13: 0.5 | I13: =ROUND(Table1[[#This Row],[Price per Unit]],2) -> 0.5 | J13: 10000 | K13: =H13*J13 -> 5000 | L13: =K13*M13 -> 1250 | M13: 0.25 | N13: =YEAR(C13) -> 2021 | O13: =MONTH(C13) -> 2 | P13: =TEXT(DATE(Table1[[#This Row],[Year]],Table1[[#This Row],[Month]],1),"mmm") -> Feb
A14: Sodapop | B14: 1185732 | C14: 44265 | D14: Northeast | E14: New York | F14: New York | G14: Coca-Cola | H14: 0.5 | I14: =ROUND(Table1[[#This Row],[Price per Unit]],2) -> 0.5 | J14: 12200 | K14: =H14*J14 -> 6100 | L14: =K14*M14 -> 3050 | M14: 0.5 | N14: =YEAR(C14) -> 2021 | O14: =MONTH(C14) -> 3 | P14: =TEXT(DATE(Table1[[#This Row],[Year]],Table1[[#This Row],[Month]],1),"mmm") -> Mar | Y14: Total Sales | Z14: Revenue / Sales
A15: Sodapop | B15: 1185732 | C15: 44265 | D15: Northeast | E15: New York | F15: New York | G15: Diet Coke | H15: 0.5 | I15: =ROUND(Table1[[#This Row],[Price per Unit]],2) -> 0.5 | J15: 9250 | K15: =H15*J15 -> 4625 | L15: =K15*M15 -> 1387.5 | M15: 0.3 | N15: =YEAR(C15) -> 2021 | O15: =MONTH(C15) -> 3 | P15: =TEXT(DATE(Table1[[#This Row],[Year]],Table1[[#This Row],[Month]],1),"mmm") -> Mar
A16: Sodapop | B16: 1185732 | C16: 44265 | D16: Northeast | E16: New York | F16: New York | G16: Sprite | H16: 0.4 | I16: =ROUND(Table1[[#This Row],[Price per Unit]],2) -> 0.4 | J16: 9500 | K16: =H16*J16 -> 3800 | L16: =K16*M16 -> 1330 | M16: 0.35 | N16: =YEAR(C16) -> 2021 | O16: =MONTH(C16) -> 3 | P16: =TEXT(DATE(Table1[[#This Row],[Year]],Table1[[#This Row],[Month]],1),"mmm") -> Mar | Y16: Operating Profit | Z16: Profit
A17: Sodapop | B17: 1185732 | C17: 44265 | D17: Northeast | E17: New York | F17: New York | G17: Fanta | H17: 0.45 | I17: =ROUND(Table1[[#This Row],[Price per Unit]],2) -> 0.45 | J17: 8000 | K17: =H17*J17 -> 3600 | L17: =K17*M17 -> 1260 | M17: 0.35 | N17: =YEAR(C17) -> 2021 | O17: =MONTH(C17) -> 3 | P17: =TEXT(DATE(Table1[[#This Row],[Year]],Table1[[#This Row],[Month]],1),"mmm") -> Mar | R17: {=_xlfn.UNIQUE(F:F)} -> City | S17: {=_xlfn.UNIQUE(D:D)} -> Region | T17: {=_xlfn.UNIQUE(E:E)} -> State | U17: {=_xlfn.UNIQUE(G:G)} -> Beverage Brand | V17: {=_xlfn.UNIQUE(A:A)} -> Retailer
A18: Sodapop | B18: 1185732 | C18: 44265 | D18: Northeast | E18: New York | F18: New York | G18: Powerade | H18: 0.6 | I18: =ROUND(Table1[[#This Row],[Price per Unit]],2) -> 0.6 | J18: 8500 | K18: =H18*J18 -> 5100 | L18: =K18*M18 -> 1530 | M18: 0.3 | N18: =YEAR(C18) -> 2021 | O18: =MONTH(C18) -> 3 | P18: =TEXT(DATE(Table1[[#This Row],[Year]],Table1[[#This Row],[Month]],1),"mmm") -> Mar | R18: New York | S18: Northeast | T18: New York | U18: Coca-Cola | V18: Sodapop | Y18: Operating Margin | Z18: Efficiency
A19: Sodapop | B19: 1185732 | C19: 44265 | D19: Northeast | E19: New York | F19: New York | G19: Dasani Water | H19: 0.5 | I19: =ROUND(Table1[[#This Row],[Price per Unit]],2) -> 0.5 | J19: 9500 | K19: =H19*J19 -> 4750 | L19: =K19*M19 -> 1187.5 | M19: 0.25 | N19: =YEAR(C19) -> 2021 | O19: =MONTH(C19) -> 3 | P19: =TEXT(DATE(Table1[[#This Row],[Year]],Table1[[#This Row],[Month]],1),"mmm") -> Mar | R19: Houston | S19: South | T19: Texas | U19: Diet Coke | V19: BevCo
A20: Sodapop | B20: 1185732 | C20: 44297 | D20: Northeast | E20: New York | F20: New York | G20: Coca-Cola | H20: 0.5 | I20: =ROUND(Table1[[#This Row],[Price per Unit]],2) -> 0.5 | J20: 12000 | K20: =H20*J20 -> 6000 | L20: =K20*M20 -> 3000 | M20: 0.5 | N20: =YEAR(C20) -> 2021 | O20: =MONTH(C20) -> 4 | P20: =TEXT(DATE(Table1[[#This Row],[Year]],Table1[[#This Row],[Month]],1),"mmm") -> Apr | R20: San Francisco | S20: West | T20: California | U20: Sprite | V20: FizzySip
A21: Sodapop | B21: 1185732 | C21: 44297 | D21: Northeast | E21: New York | F21: New York | G21: Diet Coke | H21: 0.5 | I21: =ROUND(Table1[[#This Row],[Price per Unit]],2) -> 0.5 | J21: 9000 | K21: =H21*J21 -> 4500 | L21: =K21*M21 -> 1350 | M21: 0.3 | N21: =YEAR(C21) -> 2021 | O21: =MONTH(C21) -> 4 | P21: =TEXT(DATE(Table1[[#This Row],[Year]],Table1[[#This Row],[Month]],1),"mmm") -> Apr | R21: Los Angeles | S21: Midwest | T21: Illinois | U21: Fanta | V21: DreamCo
A22: Sodapop | B22: 1185732 | C22: 44297 | D22: Northeast | E22: New York | F22: New York | G22: Sprite | H22: 0.4 | I22: =ROUND(Table1[[#This Row],[Price per Unit]],2) -> 0.4 | J22: 9000 | K22: =H22*J22 -> 3600 | L22: =K22*M22 -> 1260 | M22: 0.35 | N22: =YEAR(C22) -> 2021 | O22: =MONTH(C22) -> 4 | P22: =TEXT(DATE(Table1[[#This Row],[Year]],Table1[[#This Row],[Month]],1),"mmm") -> Apr | R22: Chicago | S22: Southeast | T22: Pennsylvania | U22: Powerade | V22: 0 | Y22: Dimensions | Z22: These group data — they don’t measure performance.
A23: Sodapop | B23: 1185732 | C23: 44297 | D23: Northeast | E23: New York | F23: New York | G23: Fanta | H23: 0.45 | I23: =ROUND(Table1[[#This Row],[Price per Unit]],2) -> 0.45 | J23: 8250 | K23: =H23*J23 -> 3712.5 | L23: =K23*M23 -> 1299.375 | M23: 0.35 | N23: =YEAR(C23) -> 2021 | O23: =MONTH(C23) -> 4 | P23: =TEXT(DATE(Table1[[#This Row],[Year]],Table1[[#This Row],[Month]],1),"mmm") -> Apr | R23: Dallas | S23: 0 | T23: Nevada | U23: Dasani Water | Y23: example | Z23: Retailer, Retailer ID, Region, State, City, Beverage Brand
A24: Sodapop | B24: 1185732 | C24: 44297 | D24: Northeast | E24: New York | F24: New York | G24: Powerade | H24: 0.6 | I24: =ROUND(Table1[[#This Row],[Price per Unit]],2) -> 0.6 | J24: 8250 | K24: =H24*J24 -> 4950 | L24: =K24*M24 -> 1485 | M24: 0.3 | N24: =YEAR(C24) -> 2021 | O24: =MONTH(C24) -> 4 | P24: =TEXT(DATE(Table1[[#This Row],[Year]],Table1[[#This Row],[Month]],1),"mmm") -> Apr | R24: Philadelphia | T24: Colorado | U24: 0
A25: Sodapop | B25: 1185732 | C25: 44297 | D25: Northeast | E25: New York | F25: New York | G25: Dasani Water | H25: 0.5 | I25: =ROUND(Table1[[#This Row],[Price per Unit]],2) -> 0.5 | J25: 9500 | K25: =H25*J25 -> 4750 | L25: =K25*M25 -> 1187.5 | M25: 0.25 | N25: =YEAR(C25) -> 2021 | O25: =MONTH(C25) -> 4 | P25: =TEXT(DATE(Table1[[#This Row],[Year]],Table1[[#This Row],[Month]],1),"mmm") -> Apr | R25: Las Vegas | T25: Washington | Z25: Key Business Takeaways
A26: Sodapop | B26: 1185732 | C26: 44326 | D26: Northeast | E26: New York | F26: New York | G26: Coca-Cola | H26: 0.6 | I26: =ROUND(Table1[[#This Row],[Price per Unit]],2) -> 0.6 | J26: 12200 | K26: =H26*J26 -> 7320 | L26: =K26*M26 -> 3660 | M26: 0.5 | N26: =YEAR(C26) -> 2021 | O26: =MONTH(C26) -> 5 | P26: =TEXT(DATE(Table1[[#This Row],[Year]],Table1[[#This Row],[Month]],1),"mmm") -> May | R26: Denver | T26: Florida | W26: Coca-Cola
A27: Sodapop | B27: 1185732 | C27: 44326 | D27: Northeast | E27: New York | F27: New York | G27: Diet Coke | H27: 0.55 | I27: =ROUND(Table1[[#This Row],[Price per Unit]],2) -> 0.55 | J27: 9250 | K27: =H27*J27 -> 5087.5 | L27: =K27*M27 -> 1526.25 | M27: 0.3 | N27: =YEAR(C27) -> 2021 | O27: =MONTH(C27) -> 5 | P27: =TEXT(DATE(Table1[[#This Row],[Year]],Table1[[#This Row],[Month]],1),"mmm") -> May | R27: Seattle | T27: Minnesota | W27: Diet Coke | Z27: Sales ≠ Profit
A28: Sodapop | B28: 1185732 | C28: 44326 | D28: Northeast | E28: New York | F28: New York | G28: Sprite | H28: 0.5 | I28: =ROUND(Table1[[#This Row],[Price per Unit]],2) -> 0.5 | J28: 9000 | K28: =H28*J28 -> 4500 | L28: =K28*M28 -> 1575 | M28: 0.35 | N28: =YEAR(C28) -> 2021 | O28: =MONTH(C28) -> 5 | P28: =TEXT(DATE(Table1[[#This Row],[Year]],Table1[[#This Row],[Month]],1),"mmm") -> May | R28: Miami | T28: Montana | W28: Sprite
A29: Sodapop | B29: 1185732 | C29: 44326 | D29: Northeast | E29: New York | F29: New York | G29: Fanta | H29: 0.5 | I29: =ROUND(Table1[[#This Row],[Price per Unit]],2) -> 0.5 | J29: 8500 | K29: =H29*J29 -> 4250 | L29: =K29*M29 -> 1487.5 | M29: 0.35 | N29: =YEAR(C29) -> 2021 | O29: =MONTH(C29) -> 5 | P29: =TEXT(DATE(Table1[[#This Row],[Year]],Table1[[#This Row],[Month]],1),"mmm") -> May | R29: Minneapolis | T29: Tennessee | W29: Fanta | Z29: Volume ≠ Efficiency
A30: Sodapop | B30: 1185732 | C30: 44326 | D30: Northeast | E30: New York | F30: New York | G30: Powerade | H30: 0.6 | I30: =ROUND(Table1[[#This Row],[Price per Unit]],2) -> 0.6 | J30: 8750 | K30: =H30*J30 -> 5250 | L30: =K30*M30 -> 1575 | M30: 0.3 | N30: =YEAR(C30) -> 2021 | O30: =MONTH(C30) -> 5 | P30: =TEXT(DATE(Table1[[#This Row],[Year]],Table1[[#This Row],[Month]],1),"mmm") -> May | R30: Billings | T30: Nebraska | W30: Powerade
A31: Sodapop | B31: 1185732 | C31: 44326 | D31: Northeast | E31: New York | F31: New York | G31: Dasani Water | H31: 0.65 | I31: =ROUND(Table1[[#This Row],[Price per Unit]],2) -> 0.65 | J31: 10000 | K31: =H31*J31 -> 6500 | L31: =K31*M31 -> 1625 | M31: 0.25 | N31: =YEAR(C31) -> 2021 | O31: =MONTH(C31) -> 5 | P31: =TEXT(DATE(Table1[[#This Row],[Year]],Table1[[#This Row],[Month]],1),"mmm") -> May | R31: Knoxville | T31: Alabama | W31: Dasani Water | Z31: Margin is the true decision metric
A32: Sodapop | B32: 1185732 | C32: 44359 | D32: Northeast | E32: New York | F32: New York | G32: Coca-Cola | H32: 0.6 | I32: =ROUND(Table1[[#This Row],[Price per Unit]],2) -> 0.6 | J32: 12500 | K32: =H32*J32 -> 7500 | L32: =K32*M32 -> 3750 | M32: 0.5 | N32: =YEAR(C32) -> 2021 | O32: =MONTH(C32) -> 6 | P32: =TEXT(DATE(Table1[[#This Row],[Year]],Table1[[#This Row],[Month]],1),"mmm") -> Jun | R32: Omaha | T32: Maine
A33: Sodapop | B33: 1185732 | C33: 44359 | D33: Northeast | E33: New York | F33: New York | G33: Diet Coke | H33: 0.55 | I33: =ROUND(Table1[[#This Row],[Price per Unit]],2) -> 0.55 | J33: 10000 | K33: =H33*J33 -> 5500 | L33: =K33*M33 -> 1650 | M33: 0.3 | N33: =YEAR(C33) -> 2021 | O33: =MONTH(C33) -> 6 | P33: =TEXT(DATE(Table1[[#This Row],[Year]],Table1[[#This Row],[Month]],1),"mmm") -> Jun | R33: Birmingham | T33: Alaska | Z33: Pricing strategy must be retailer- and region-specific
A34: Sodapop | B34: 1185732 | C34: 44359 | D34: Northeast | E34: New York | F34: New York | G34: Sprite | H34: 0.5 | I34: =ROUND(Table1[[#This Row],[Price per Unit]],2) -> 0.5 | J34: 9250 | K34: =H34*J34 -> 4625 | L34: =K34*M34 -> 1618.75 | M34: 0.35 | N34: =YEAR(C34) -> 2021 | O34: =MONTH(C34) -> 6 | P34: =TEXT(DATE(Table1[[#This Row],[Year]],Table1[[#This Row],[Month]],1),"mmm") -> Jun | R34: Portland | T34: Hawaii
A35: Sodapop | B35: 1185732 | C35: 44359 | D35: Northeast | E35: New York | F35: New York | G35: Fanta | H35: 0.5 | I35: =ROUND(Table1[[#This Row],[Price per Unit]],2) -> 0.5 | J35: 9000 | K35: =H35*J35 -> 4500 | L35: =K35*M35 -> 1575 | M35: 0.35 | N35: =YEAR(C35) -> 2021 | O35: =MONTH(C35) -> 6 | P35: =TEXT(DATE(Table1[[#This Row],[Year]],Table1[[#This Row],[Month]],1),"mmm") -> Jun | R35: Anchorage | T35: Wyoming
A36: Sodapop | B36: 1185732 | C36: 44359 | D36: Northeast | E36: New York | F36: New York | G36: Powerade | H36: 0.6 | I36: =ROUND(Table1[[#This Row],[Price per Unit]],2) -> 0.6 | J36: 9000 | K36: =H36*J36 -> 5400 | L36: =K36*M36 -> 1620 | M36: 0.3 | N36: =YEAR(C36) -> 2021 | O36: =MONTH(C36) -> 6 | P36: =TEXT(DATE(Table1[[#This Row],[Year]],Table1[[#This Row],[Month]],1),"mmm") -> Jun | R36: Honolulu | T36: Virginia
A37: Sodapop | B37: 1185732 | C37: 44359 | D37: Northeast | E37: New York | F37: New York | G37: Dasani Water | H37: 0.65 | I37: =ROUND(Table1[[#This Row],[Price per Unit]],2) -> 0.65 | J37: 10500 | K37: =H37*J37 -> 6825 | L37: =K37*M37 -> 1706.25 | M37: 0.25 | N37: =YEAR(C37) -> 2021 | O37: =MONTH(C37) -> 6 | P37: =TEXT(DATE(Table1[[#This Row],[Year]],Table1[[#This Row],[Month]],1),"mmm") -> Jun | R37: Orlando | T37: Michigan
A38: Sodapop | B38: 1185732 | C38: 44387 | D38: Northeast | E38: New York | F38: New York | G38: Coca-Cola | H38: 0.6 | I38: =ROUND(Table1[[#This Row],[Price per Unit]],2) -> 0.6 | J38: 12750 | K38: =H38*J38 -> 7650 | L38: =K38*M38 -> 3825 | M38: 0.5 | N38: =YEAR(C38) -> 2021 | O38: =MONTH(C38) -> 7 | P38: =TEXT(DATE(Table1[[#This Row],[Year]],Table1[[#This Row],[Month]],1),"mmm") -> Jul | R38: Albany | T38: Missouri | W38: =COUNTA(R18:R69) -> 52
A39: Sodapop | B39: 1185732 | C39: 44387 | D39: Northeast | E39: New York | F39: New York | G39: Diet Coke | H39: 0.55 | I39: =ROUND(Table1[[#This Row],[Price per Unit]],2) -> 0.55 | J39: 10250 | K39: =H39*J39 -> 5637.5 | L39: =K39*M39 -> 1691.25 | M39: 0.3 | N39: =YEAR(C39) -> 2021 | O39: =MONTH(C39) -> 7 | P39: =TEXT(DATE(Table1[[#This Row],[Year]],Table1[[#This Row],[Month]],1),"mmm") -> Jul | R39: Cheyenne | T39: Utah
A40: Sodapop | B40: 1185732 | C40: 44387 | D40: Northeast | E40: New York | F40: New York | G40: Sprite | H40: 0.5 | I40: =ROUND(Table1[[#This Row],[Price per Unit]],2) -> 0.5 | J40: 9500 | K40: =H40*J40 -> 4750 | L40: =K40*M40 -> 1662.5 | M40: 0.35 | N40: =YEAR(C40) -> 2021 | O40: =MONTH(C40) -> 7 | P40: =TEXT(DATE(Table1[[#This Row],[Year]],Table1[[#This Row],[Month]],1),"mmm") -> Jul | R40: Richmond | T40: Oregon
...

Sheet KPIs
J3: Clearly shows who drives revenue.
E4: KPIS
J5: Revenue by retailer | N5: Units Sales by retailer | R5: Profit by retailer | W5: Units Sold by Regions | AA5: Revenue by Regions | AE5: Profit by Regions | AJ5: Units Sold by Region | AO5: Units Sold by Retailer | AU5: Price per Unit | BF5: Performing - Operating Margin by City | BI5: underperforming - Operating Margin by City
E6: Values | J6: Retailers | K6: Sum of Total Sales | N6: Retailers | O6: Sum of Units Sold | R6: Retailers | S6: Sum of Operating Profit | T6: Sum of Operating Profit2 | W6: Regions | X6: Sum of Units Sold | AA6: Regions | AB6: Sum of Total Sales | AE6: Regions | AF6: Sum of Operating Profit | AG6: Sum of Operating Profit2 | AJ6: Region | AK6: Sum of Total Sales | AL6: Sum of Operating Profit | AO6: Retailer | AP6: Sum of Total Sales | AQ6: Sum of Operating Profit | AU6: Price Per unit | AV6: Sum of Units Sold | AW6: Sum of Total Sales | AX6: Sum of Operating Profit | AZ6: =AU6 -> Price Per unit | BA6: =AV6 -> Sum of Units Sold | BB6: =AW6 -> Sum of Total Sales | BC6: =AX6 -> Sum of Operating Profit | BF6: City | BG6: Average of Operating Margin | BI6: City | BJ6: Average of Operating Margin
E7: Sum of Total Sales | F7: 8684027.5 | G7: =F7 -> 8684027.5 | J7: BevCo | K7: 1291535 | N7: BevCo | O7: 3064800 | R7: DreamCo | S7: 147890 | T7: 147890 | W7: Midwest | X7: 2782950 | AA7: Midwest | AB7: 1150110 | AE7: Midwest | AF7: 437471.5 | AG7: 437471.5 | AJ7: Midwest | AK7: 1150110 | AL7: 437471.5 | AO7: BevCo | AP7: 1291535 | AQ7: 542046.12 | AU7: 0.1 | AV7: 30250 | AW7: 3025 | AX7: 1137.5 | AZ7: =AU7 -> 0.1 | BA7: =AV7 -> 30250 | BB7: =AW7 -> 3025 | BC7: =AX7 -> 1137.5 | BF7: Birmingham | BG7: 0.5 | BI7: Anchorage | BJ7: 0.25
E8: Sum of Units Sold | F8: 17148250 | G8: =F8 -> 17148250 | J8: DreamCo | K8: 404412.5 | N8: DreamCo | O8: 820500 | R8: BevCo | S8: 542046.12 | T8: 542046.12 | W8: Northeast | X8: 3394550 | AA8: Northeast | AB8: 1788347.5 | AE8: South | AF8: 542046.12 | AG8: 542046.12 | AJ8: Northeast | AK8: 1788347.5 | AL8: 629546 | AO8: DreamCo | AP8: 404412.5 | AQ8: 147890 | AU8: 0.15 | AV8: 112500 | AW8: 16875 | AX8: 6455.625 | AZ8: =AU8 -> 0.15 | BA8: =AV8 -> 112500 | BB8: =AW8 -> 16875 | BC8: =AX8 -> 6455.625 | BF8: Knoxville | BG8: 0.45 | BI8: Seattle | BJ8: 0.25833333
E9: Sum of Operating Profit | F9: 3173631.9 | G9: =F9 -> 3173631.9 | J9: FizzySip | K9: 2584450 | N9: FizzySip | O9: 4109000 | R9: FizzySip | S9: 835759.38 | T9: 835759.38 | W9: South | X9: 3064800 | AA9: South | AB9: 1291535 | AE9: Northeast | AF9: 629546 | AG9: 629546 | AJ9: South | AK9: 1291535 | AL9: 542046.12 | AO9: FizzySip | AP9: 2584450 | AQ9: 835759.38 | AU9: 0.2 | AV9: 364200 | AW9: 72840 | AX9: 27776.5 | AZ9: =AU9 -> 0.2 | BA9: =AV9 -> 364200 | BB9: =AW9 -> 72840 | BC9: =AX9 -> 27776.5 | BF9: Richmond | BG9: 0.41666667 | BI9: Providence | BJ9: 0.275
E10: Average of Operating Margin | F10: 0.36310442 | J10: Sodapop | K10: 4403630 | N10: Sodapop | O10: 9153950 | R10: Sodapop | S10: 1647936.4 | T10: 1647936.4 | W10: Southeast | X10: 3304450 | AA10: Southeast | AB10: 1618935 | AE10: Southeast | AF10: 641553.88 | AG10: 641553.88 | AJ10: Southeast | AK10: 1618935 | AL10: 641553.88 | AO10: Sodapop | AP10: 4403630 | AQ10: 1647936.4 | AU10: 0.25 | AV10: 572450 | AW10: 143112.5 | AX10: 53736.875 | AZ10: =AU10 -> 0.25 | BA10: =AV10 -> 572450 | BB10: =AW10 -> 143112.5 | BC10: =AX10 -> 53736.875 | BF10: Billings | BG10: 0.40833333 | BI10: Manchester | BJ10: 0.29166667
E11: Average of Price per Unit | F11: 0.48738426 | J11: Grand Total | K11: 8684027.5 | N11: Grand Total | O11: 17148250 | R11: Grand Total | S11: 3173631.9 | T11: 3173631.9 | W11: West | X11: 4601500 | AA11: West | AB11: 2835100 | AE11: West | AF11: 923014.38 | AG11: 923014.38 | AJ11: West | AK11: 2835100 | AL11: 923014.38 | AO11: Grand Total | AP11: 8684027.5 | AQ11: 3173631.9 | AU11: 0.3 | AV11: 864900 | AW11: 259470 | AX11: 98025.75 | AZ11: =AU11 -> 0.3 | BA11: =AV11 -> 864900 | BB11: =AW11 -> 259470 | BC11: =AX11 -> 98025.75 | BF11: Louisville | BG11: 0.4 | BI11: San Francisco | BJ11: 0.3
W12: Grand Total | X12: 17148250 | AA12: Grand Total | AB12: 8684027.5 | AE12: Grand Total | AF12: 3173631.9 | AG12: 3173631.9 | AJ12: Grand Total | AK12: 8684027.5 | AL12: 3173631.9 | AU12: 0.35 | AV12: 1318900 | AW12: 461615 | AX12: 179097.62 | AZ12: =AU12 -> 0.35 | BA12: =AV12 -> 1318900 | BB12: =AW12 -> 461615 | BC12: =AX12 -> 179097.62 | BF12: Charlotte | BG12: 0.4 | BI12: Honolulu | BJ12: 0.3
AU13: 0.4 | AV13: 1735950 | AW13: 694380 | AX13: 259386 | AZ13: =AU13 -> 0.4 | BA13: =AV13 -> 1735950 | BB13: =AW13 -> 694380 | BC13: =AX13 -> 259386 | BF13: Grand Total | BG13: 0.42916667 | BI13: Grand Total | BJ13: 0.27916667
AU14: 0.45 | AV14: 2175150 | AW14: 978817.5 | AX14: 365933.25 | AZ14: =AU14 -> 0.45 | BA14: =AV14 -> 2175150 | BB14: =AW14 -> 978817.5 | BC14: =AX14 -> 365933.25
AU15: 0.5 | AV15: 2440100 | AW15: 1220050 | AX15: 451996.25 | AZ15: =AU15 -> 0.5 | BA15: =AV15 -> 2440100 | BB15: =AW15 -> 1220050 | BC15: =AX15 -> 451996.25
AU16: 0.55 | AV16: 2242650 | AW16: 1233457.5 | AX16: 448047.88 | AZ16: =AU16 -> 0.55 | BA16: =AV16 -> 2242650 | BB16: =AW16 -> 1233457.5 | BC16: =AX16 -> 448047.88
AU17: 0.6 | AV17: 1871650 | AW17: 1122990 | AX17: 422499 | AZ17: =AU17 -> 0.6 | BA17: =AV17 -> 1871650 | BB17: =AW17 -> 1122990 | BC17: =AX17 -> 422499
E18: other kpis metrics | AU18: 0.65 | AV18: 1464550 | AW18: 951957.5 | AX18: 351607.75 | AZ18: =AU18 -> 0.65 | BA18: =AV18 -> 1464550 | BB18: =AW18 -> 951957.5 | BC18: =AX18 -> 351607.75
E19: Total Retailers | F19: =COUNTA(_xlfn.UNIQUE(Table1[Retailer])) -> 4 | AU19: 0.7 | AV19: 750000 | AW19: 525000 | AX19: 189245 | AZ19: =AU19 -> 0.7 | BA19: =AV19 -> 750000 | BB19: =AW19 -> 525000 | BC19: =AX19 -> 189245
E20: Total Beverage Brands | F20: =COUNTA(_xlfn.UNIQUE(Table1[Beverage Brand])) -> 6 | AU20: 0.75 | AV20: 394500 | AW20: 295875 | AX20: 102768.75 | AZ20: =AU20 -> 0.75 | BA20: =AV20 -> 394500 | BB20: =AW20 -> 295875 | BC20: =AX20 -> 102768.75
E21: Total Regions | F21: =COUNTA(_xlfn.UNIQUE(Table1[Region])) -> 5 | AU21: 0.8 | AV21: 315000 | AW21: 252000 | AX21: 70930 | AZ21: =AU21 -> 0.8 | BA21: =AV21 -> 315000 | BB21: =AW21 -> 252000 | BC21: =AX21 -> 70930
E22: Total City Covered | F22: =COUNTA(_xlfn.UNIQUE(Table1[City])) -> 52 | AU22: 0.85 | AV22: 197500 | AW22: 167875 | AX22: 48705 | AZ22: =AU22 -> 0.85 | BA22: =AV22 -> 197500 | BB22: =AW22 -> 167875 | BC22: =AX22 -> 48705
E23: Total States Covered | F23: =COUNTA(_xlfn.UNIQUE(Table1[State])) -> 50 | AU23: 0.9 | AV23: 128750 | AW23: 115875 | AX23: 39937.5 | AZ23: =AU23 -> 0.9 | BA23: =AV23 -> 128750 | BB23: =AW23 -> 115875 | BC23: =AX23 -> 39937.5
AU24: 0.95 | AV24: 90750 | AW24: 86212.5 | AX24: 28535.625 | AZ24: =AU24 -> 0.95 | BA24: =AV24 -> 90750 | BB24: =AW24 -> 86212.5 | BC24: =AX24 -> 28535.625
AU25: 1 | AV25: 24500 | AW25: 24500 | AX25: 7300 | AZ25: =AU25 -> 1 | BA25: =AV25 -> 24500 | BB25: =AW25 -> 24500 | BC25: =AX25 -> 7300
AU26: 1.05 | AV26: 26000 | AW26: 27300 | AX26: 8190 | AZ26: =AU26 -> 1.05 | BA26: =AV26 -> 26000 | BB26: =AW26 -> 27300 | BC26: =AX26 -> 8190
AU27: 1.1 | AV27: 28000 | AW27: 30800 | AX27: 12320 | AZ27: =AU27 -> 1.1 | BA27: =AV27 -> 28000 | BB27: =AW27 -> 30800 | BC27: =AX27 -> 12320
AU28: Grand Total | AV28: 17148250 | AW28: 8684027.5 | AX28: 3173631.9

Sheet Sales & Profitability Analysis
B3: Retailer-wise Analysis | H3: Sales vs operating Profit by region | AE3: Sales vs operating Profit by Retailer | AR3: Sales vs operating Profit by Retailer | AX3: Sales vs operating Profit by Region
H4: Region | I4: =$H5 -> Northeast | K4: =$H6 -> South | M4: =$H7 -> West | O4: =$H8 -> Midwest | Q4: =$H9 -> Southeast | S4: No Filter | AE4: Retailer | AF4: =AE5 -> Sodapop | AH4: =AE6 -> BevCo | AJ4: =AE7 -> FizzySip | AL4: =AE8 -> DreamCo | AN4: No Filter | AR4: Retailer | AS4: Sum of Total Sales | AT4: Sum of Operating Profit | AU4: Sum of Units Sold | AX4: Region | AY4: Sum of Total Sales | AZ4: Sum of Operating Profit | BA4: Sum of Units Sold
B5: Retailer | C5: Sum of Units Sold | D5: Sum of Total Sales | E5: Sum of Operating Profit | H5: {=_xlfn.UNIQUE(Table1[Region])} -> Northeast | I5: Sales | J5: operating profit | K5: Sales | L5: operating profit | M5: Sales | N5: operating profit | O5: Sales | P5: operating profit | Q5: Sales | R5: operating profit | S5: Sales | T5: Profit | AE5: {=_xlfn.UNIQUE(Table1[Retailer])} -> Sodapop | AF5: Sales | AG5: operating profit | AH5: Sales | AI5: operating profit | AJ5: Sales | AK5: operating profit | AL5: Sales | AM5: operating profit | AN5: Sales | AO5: Profit | AR5: BevCo | AS5: 1291535 | AT5: 542046.12 | AU5: 3064800 | AX5: Midwest | AY5: 1150110 | AZ5: 437471.5 | BA5: 2782950 | BE5: Sum of Total Sales | BF5: Column Labels | BM5: Sum of Total Sales | BN5: Column Labels
B6: BevCo | C6: 3064800 | D6: 1291535 | E6: 542046.12 | H6: South | I6: {=_xlfn._xlws.FILTER(Table1[Total Sales],Table1[Region]=I4)} -> 6000 | J6: {=_xlfn._xlws.FILTER(Table1[Total Sales],Table1[Region]=I4)} -> 6000 | K6: {=_xlfn._xlws.FILTER(Table1[Total Sales],Table1[Region]=K4)} -> 2250 | L6: {=_xlfn._xlws.FILTER(Table1[Operating Profit],Table1[Region]=K4)} -> 787.5 | M6: {=_xlfn._xlws.FILTER(Table1[Total Sales],Table1[Region]=M4)} -> 3100 | N6: {=_xlfn._xlws.FILTER(Table1[Operating Profit],Table1[Region]=M4)} -> 1085 | O6: {=_xlfn._xlws.FILTER(Table1[Total Sales],Table1[Region]=O4)} -> 2137.5 | P6: {=_xlfn._xlws.FILTER(Table1[Operating Profit],Table1[Region]=O4)} -> 855 | Q6: {=_xlfn._xlws.FILTER(Table1[Total Sales],Table1[Region]=Q4)} -> 4725 | R6: {=_xlfn._xlws.FILTER(Table1[Operating Profit],Table1[Region]=Q4)} -> 2126.25 | S6: {=Table1[Total Sales]} -> 6000 | T6: {=Table1[Operating Profit]} -> 3000 | AE6: BevCo | AF6: {=_xlfn._xlws.FILTER(Table1[Total Sales],Table1[Retailer]=AF4)} -> 6000 | AG6: {=_xlfn._xlws.FILTER(Table1[Total Sales],Table1[Retailer]=AF4)} -> 6000 | AH6: {=_xlfn._xlws.FILTER(Table1[Total Sales],Table1[Retailer]=AH4)} -> 2250 | AI6: {=_xlfn._xlws.FILTER(Table1[Operating Profit],Table1[Retailer]=AH4)} -> 787.5 | AJ6: {=_xlfn._xlws.FILTER(Table1[Total Sales],Table1[Retailer]=AJ4)} -> 3100 | AK6: {=_xlfn._xlws.FILTER(Table1[Operating Profit],Table1[Retailer]=AJ4)} -> 1085 | AL6: {=_xlfn._xlws.FILTER(Table1[Total Sales],Table1[Retailer]=AL4)} -> 2450 | AM6: {=_xlfn._xlws.FILTER(Table1[Operating Profit],Table1[Retailer]=AL4)} -> 980 | AN6: {=Table1[Total Sales]} -> 6000 | AO6: {=Table1[Operating Profit]} -> 3000 | AR6: DreamCo | AS6: 404412.5 | AT6: 147890 | AU6: 820500 | AX6: Northeast | AY6: 1788347.5 | AZ6: 629546 | BA6: 3394550 | BE6: Row Labels | BF6: Midwest | BG6: Northeast | BH6: South | BI6: Southeast | BJ6: West | BM6: Row Labels | BN6: BevCo | BO6: DreamCo | BP6: FizzySip | BQ6: Sodapop
B7: DreamCo | C7: 820500 | D7: 404412.5 | E7: 147890 | H7: West | I7: 5000 | J7: 5000 | K7: 3150 | L7: 1102.5 | M7: 3875 | N7: 775 | O7: 1237.5 | P7: 433.125 | Q7: 3825 | R7: 1338.75 | S7: 5000 | T7: 1500 | AE7: FizzySip | AF7: 5000 | AG7: 5000 | AH7: 3150 | AI7: 1102.5 | AJ7: 3875 | AK7: 775 | AL7: 3150 | AM7: 787.5 | AN7: 5000 | AO7: 1500 | AR7: FizzySip | AS7: 2584450 | AT7: 835759.38 | AU7: 4109000 | AX7: South | AY7: 1291535 | AZ7: 542046.12 | BA7: 3064800 | BE7: Jan | BF7: 80087.5 | BG7: 115737.5 | BH7: 70662.5 | BI7: 104750 | BJ7: 139512.5 | BM7: Jan | BN7: 70662.5 | BO7: 27787.5 | BP7: 122637.5 | BQ7: 289662.5
B8: FizzySip | C8: 4109000 | D8: 2584450 | E8: 835759.38 | H8: Midwest | I8: 4000 | J8: 4000 | K8: 2450 | L8: 857.5 | M8: 3875 | N8: 1356.25 | O8: 962.5 | P8: 336.875 | Q8: 2975 | R8: 743.75 | S8: 4000 | T8: 1400 | AE8: DreamCo | AF8: 4000 | AG8: 4000 | AH8: 2450 | AI8: 857.5 | AJ8: 3875 | AK8: 1356.25 | AL8: 3150 | AM8: 1260 | AN8: 4000 | AO8: 1400 | AR8: Sodapop | AS8: 4403630 | AT8: 1647936.4 | AU8: 9153950 | AX8: Southeast | AY8: 1618935 | AZ8: 641553.88 | BA8: 3304450 | BE8: Feb | BF8: 73762.5 | BG8: 112650 | BH8: 66475 | BI8: 99500 | BJ8: 132587.5 | BM8: Feb | BN8: 66475 | BO8: 26287.5 | BP8: 116462.5 | BQ8: 275750
B9: Sodapop | C9: 9153950 | D9: 4403630 | E9: 1647936.4 | H9: Southeast | I9: 3825 | J9: 3825 | K9: 2450 | L9: 1102.5 | M9: 3125 | N9: 937.5 | O9: 500 | P9: 200 | Q9: 2800 | R9: 840 | S9: 3825 | T9: 1338.75 | AF9: 3825 | AG9: 3825 | AH9: 2450 | AI9: 1102.5 | AJ9: 3125 | AK9: 937.5 | AL9: 2475 | AM9: 866.25 | AN9: 3825 | AO9: 1338.75 | AR9: Grand Total | AS9: 8684027.5 | AT9: 3173631.9 | AU9: 17148250 | AX9: West | AY9: 2835100 | AZ9: 923014.38 | BA9: 4601500 | BE9: Mar | BF9: 68072.5 | BG9: 104985 | BH9: 65845 | BI9: 86102.5 | BJ9: 158525 | BM9: Mar | BN9: 65845 | BO9: 26162.5 | BP9: 142462.5 | BQ9: 249060
B10: Grand Total | C10: 17148250 | D10: 8684027.5 | E10: 3173631.9 | I10: 5400 | J10: 5400 | K10: 2200 | L10: 660 | M10: 3162.5 | N10: 1581.25 | O10: 962.5 | P10: 336.875 | Q10: 4125 | R10: 1443.75 | S10: 5400 | T10: 1620 | AF10: 5400 | AG10: 5400 | AH10: 2200 | AI10: 660 | AJ10: 3162.5 | AK10: 1581.25 | AL10: 2500 | AM10: 1375 | AN10: 5400 | AO10: 1620 | AX10: Grand Total | AY10: 8684027.5 | AZ10: 3173631.9 | BA10: 17148250 | BE10: Apr | BF10: 65762.5 | BG10: 101175 | BH10: 60662.5 | BI10: 88525 | BJ10: 178762.5 | BM10: Apr | BN10: 60662.5 | BO10: 28537.5 | BP10: 160650 | BQ10: 245037.5
I11: 5000 | J11: 5000 | K11: 2450 | L11: 1225 | M11: 3875 | N11: 581.25 | O11: 1237.5 | P11: 618.75 | Q11: 3825 | R11: 1912.5 | S11: 5000 | T11: 1250 | AF11: 5000 | AG11: 5000 | AH11: 2450 | AI11: 1225 | AJ11: 3875 | AK11: 581.25 | AL11: 3150 | AM11: 630 | AN11: 5000 | AO11: 1250 | BE11: May | BF11: 97392.5 | BG11: 154247.5 | BH11: 89965 | BI11: 133555 | BJ11: 198412.5 | BM11: May | BN11: 89965 | BO11: 29725 | BP11: 179525 | BQ11: 374357.5
I12: 6250 | J12: 6250 | K12: 2125 | L12: 743.75 | M12: 3300 | N12: 1155 | O12: 2362.5 | P12: 945 | Q12: 4950 | R12: 2227.5 | S12: 6250 | T12: 3125 | AF12: 6250 | AG12: 6250 | AH12: 2125 | AI12: 743.75 | AJ12: 3300 | AK12: 1155 | AL12: 2625 | AM12: 1050 | AN12: 6250 | AO12: 3125 | AR12: =AR4 -> Retailer | AS12: =AS4 -> Sum of Total Sales | AT12: =AT4 -> Sum of Operating Profit | AU12: =AU4 -> Sum of Units Sold | AX12: =AX4 -> Region | AY12: =AY4 -> Sum of Total Sales | AZ12: =AZ4 -> Sum of Operating Profit | BA12: =BA4 -> Sum of Units Sold | BE12: Jun | BF12: 101637.5 | BG12: 176437.5 | BH12: 134537.5 | BI12: 162687.5 | BJ12: 328537.5 | BM12: Jun | BN12: 134537.5 | BO12: 36250 | BP12: 306475 | BQ12: 426575
I13: 4500 | J13: 4500 | K13: 2975 | L13: 1041.25 | M13: 3625 | N13: 725 | O13: 787.5 | P13: 275.625 | Q13: 3375 | R13: 1181.25 | S13: 4500 | T13: 1350 | AF13: 4500 | AG13: 4500 | AH13: 2975 | AI13: 1041.25 | AJ13: 3625 | AK13: 725 | AL13: 2925 | AM13: 731.25 | AN13: 4500 | AO13: 1350 | AR13: =AR5 -> BevCo | AS13: =AS5 -> 1291535 | AT13: =AT5 -> 542046.12 | AU13: =AU5 -> 3064800 | AX13: =AX5 -> Midwest | AY13: =AY5 -> 1150110 | AZ13: =AZ5 -> 437471.5 | BA13: =BA5 -> 2782950 | BE13: Jul | BF13: 131387.5 | BG13: 187900 | BH13: 157912.5 | BI13: 191425 | BJ13: 372812.5 | BM13: Jul | BN13: 157912.5 | BO13: 37962.5 | BP13: 349812.5 | BQ13: 495750
I14: 3800 | J14: 3800 | K14: 2362.5 | L14: 826.875 | M14: 3625 | N14: 1268.75 | O14: 787.5 | P14: 275.625 | Q14: 2800 | R14: 700 | S14: 3800 | T14: 1330 | AF14: 3800 | AG14: 3800 | AH14: 2362.5 | AI14: 826.875 | AJ14: 3625 | AK14: 1268.75 | AL14: 3037.5 | AM14: 1215 | AN14: 3800 | AO14: 1330 | AR14: =AR6 -> DreamCo | AS14: =AS6 -> 404412.5 | AT14: =AT6 -> 147890 | AU14: =AU6 -> 820500 | AX14: =AX6 -> Northeast | AY14: =AY6 -> 1788347.5 | AZ14: =AZ6 -> 629546 | BA14: =BA6 -> 3394550 | BE14: Aug | BF14: 120312.5 | BG14: 173362.5 | BH14: 152275 | BI14: 170700 | BJ14: 328625 | BM14: Aug | BN14: 152275 | BO14: 40075 | BP14: 304175 | BQ14: 448750
I15: 3712.5 | J15: 3712.5 | K15: 2187.5 | L15: 984.375 | M15: 2875 | N15: 862.5 | O15: 400 | P15: 160 | Q15: 2700 | R15: 810 | S15: 3712.5 | T15: 1299.375 | AF15: 3712.5 | AG15: 3712.5 | AH15: 2187.5 | AI15: 984.375 | AJ15: 2875 | AK15: 862.5 | AL15: 2362.5 | AM15: 826.875 | AN15: 3712.5 | AO15: 1299.375 | AR15: =AR7 -> FizzySip | AS15: =AS7 -> 2584450 | AT15: =AT7 -> 835759.38 | AU15: =AU7 -> 4109000 | AX15: =AX7 -> South | AY15: =AY7 -> 1291535 | AZ15: =AZ7 -> 542046.12 | BA15: =BA7 -> 3064800 | BE15: Sep | BF15: 81087.5 | BG15: 142037.5 | BH15: 117225 | BI15: 124537.5 | BJ15: 216112.5 | BM15: Sep | BN15: 117225 | BO15: 38550 | BP15: 191987.5 | BQ15: 333237.5
I16: 5400 | J16: 5400 | K16: 2000 | L16: 600 | M16: 2750 | N16: 1375 | O16: 962.5 | P16: 336.875 | Q16: 4125 | R16: 1443.75 | S16: 5400 | T16: 1620 | AF16: 5400 | AG16: 5400 | AH16: 2000 | AI16: 600 | AJ16: 2750 | AK16: 1375 | AL16: 2250 | AM16: 1237.5 | AN16: 5400 | AO16: 1620 | AR16: =AR8 -> Sodapop | AS16: =AS8 -> 4403630 | AT16: =AT8 -> 1647936.4 | AU16: =AU8 -> 9153950 | AX16: =AX8 -> Southeast | AY16: =AY8 -> 1618935 | AZ16: =AZ8 -> 641553.88 | BA16: =BA8 -> 3304450 | BE16: Oct | BF16: 82800 | BG16: 143887.5 | BH16: 81687.5 | BI16: 119525 | BJ16: 195475 | BM16: Oct | BN16: 81687.5 | BO16: 35637.5 | BP16: 172875 | BQ16: 333175
I17: 5000 | J17: 5000 | K17: 2450 | L17: 1225 | M17: 3500 | N17: 525 | O17: 1237.5 | P17: 618.75 | Q17: 3825 | R17: 1912.5 | S17: 5000 | T17: 1250 | AF17: 5000 | AG17: 5000 | AH17: 2450 | AI17: 1225 | AJ17: 3500 | AK17: 525 | AL17: 2925 | AM17: 585 | AN17: 5000 | AO17: 1250 | AX17: =AX9 -> West | AY17: =AY9 -> 2835100 | AZ17: =AZ9 -> 923014.38 | BA17: =BA9 -> 4601500 | BE17: Nov | BF17: 102420 | BG17: 173315 | BH17: 118800 | BI17: 146152.5 | BJ17: 254925 | BM17: Nov | BN17: 118800 | BO17: 36637.5 | BP17: 231487.5 | BQ17: 408687.5
I18: 6100 | J18: 6100 | K18: 2625 | L18: 918.75 | M18: 4250 | N18: 1487.5 | O18: 2475 | P18: 990 | Q18: 4815 | R18: 2166.75 | S18: 6100 | T18: 3050 | AF18: 6100 | AG18: 6100 | AH18: 2625 | AI18: 918.75 | AJ18: 4250 | AK18: 1487.5 | AL18: 2800 | AM18: 1120 | AN18: 6100 | AO18: 3050 | BE18: Dec | BF18: 145387.5 | BG18: 202612.5 | BH18: 175487.5 | BI18: 191475 | BJ18: 330812.5 | BM18: Dec | BN18: 175487.5 | BO18: 40800 | BP18: 305900 | BQ18: 523587.5
I19: 4625 | J19: 4625 | K19: 3500 | L19: 1225 | M19: 4200 | N19: 840 | O19: 1000 | P19: 350 | Q19: 3375 | R19: 1181.25 | S19: 4625 | T19: 1387.5 | AF19: 4625 | AG19: 4625 | AH19: 3500 | AI19: 1225 | AJ19: 4200 | AK19: 840 | AL19: 2925 | AM19: 731.25 | AN19: 4625 | AO19: 1387.5
I20: 3800 | J20: 3800 | K20: 2450 | L20: 857.5 | M20: 4200 | N20: 1470 | O20: 900 | P20: 315 | Q20: 2712.5 | R20: 678.125 | S20: 3800 | T20: 1330 | AF20: 3800 | AG20: 3800 | AH20: 2450 | AI20: 857.5 | AJ20: 4200 | AK20: 1470 | AL20: 2925 | AM20: 1170 | AN20: 3800 | AO20: 1330
I21: 3600 | J21: 3600 | K21: 2400 | L21: 1080 | M21: 3600 | N21: 1080 | O21: 337.5 | P21: 135 | Q21: 2500 | R21: 750 | S21: 3600 | T21: 1260 | AF21: 3600 | AG21: 3600 | AH21: 2400 | AI21: 1080 | AJ21: 3600 | AK21: 1080 | AL21: 2475 | AM21: 866.25 | AN21: 3600 | AO21: 1260
I22: 5100 | J22: 5100 | K22: 2250 | L22: 675 | M22: 3250 | N22: 1625 | O22: 750 | P22: 262.5 | Q22: 3712.5 | R22: 1299.375 | S22: 5100 | T22: 1530 | AF22: 5100 | AG22: 5100 | AH22: 2250 | AI22: 675 | AJ22: 3250 | AK22: 1625 | AL22: 2125 | AM22: 1168.75 | AN22: 5100 | AO22: 1530
I23: 4750 | J23: 4750 | K23: 2600 | L23: 1300 | M23: 4200 | N23: 630 | O23: 1125 | P23: 562.5 | Q23: 3487.5 | R23: 1743.75 | S23: 4750 | T23: 1187.5 | AF23: 4750 | AG23: 4750 | AH23: 2600 | AI23: 1300 | AJ23: 4200 | AK23: 630 | AL23: 2812.5 | AM23: 562.5 | AN23: 4750 | AO23: 1187.5
I24: 6000 | J24: 6000 | K24: 2700 | L24: 945 | M24: 5250 | N24: 1837.5 | O24: 2250 | P24: 900 | Q24: 4612.5 | R24: 2075.625 | S24: 6000 | T24: 3000 | AF24: 6000 | AG24: 6000 | AH24: 2700 | AI24: 945 | AJ24: 5250 | AK24: 1837.5 | AL24: 3600 | AM24: 1440 | AN24: 6000 | AO24: 3000
I25: 4500 | J25: 4500 | K25: 3600 | L25: 1260 | M25: 4387.5 | N25: 877.5 | O25: 750 | P25: 262.5 | Q25: 3262.5 | R25: 1141.875 | S25: 4500 | T25: 1350 | AF25: 4500 | AG25: 4500 | AH25: 3600 | AI25: 1260 | AJ25: 4387.5 | AK25: 877.5 | AL25: 3000 | AM25: 750 | AN25: 4500 | AO25: 1350
I26: 3600 | J26: 3600 | K26: 2537.5 | L26: 888.125 | M26: 4712.5 | N26: 1649.375 | O26: 600 | P26: 210 | Q26: 2537.5 | R26: 634.375 | S26: 3600 | T26: 1260 | AF26: 3600 | AG26: 3600 | AH26: 2537.5 | AI26: 888.125 | AJ26: 4712.5 | AK26: 1649.375 | AL26: 3125 | AM26: 1250 | AN26: 3600 | AO26: 1260
I27: 3712.5 | J27: 3712.5 | K27: 2500 | L27: 1125 | M27: 3750 | N27: 1125 | O27: 337.5 | P27: 135 | Q27: 2600 | R27: 780 | S27: 3712.5 | T27: 1299.375 | AF27: 3712.5 | AG27: 3712.5 | AH27: 2500 | AI27: 1125 | AJ27: 3750 | AK27: 1125 | AL27: 2362.5 | AM27: 826.875 | AN27: 3712.5 | AO27: 1299.375
I28: 4950 | J28: 4950 | K28: 2362.5 | L28: 708.75 | M28: 3412.5 | N28: 1706.25 | O28: 600 | P28: 210 | Q28: 3712.5 | R28: 1299.375 | S28: 4950 | T28: 1485 | AF28: 4950 | AG28: 4950 | AH28: 2362.5 | AI28: 708.75 | AJ28: 3412.5 | AK28: 1706.25 | AL28: 2125 | AM28: 1168.75 | AN28: 4950 | AO28: 1485
I29: 4750 | J29: 4750 | K29: 3200 | L29: 1600 | M29: 5600 | N29: 840 | O29: 1125 | P29: 562.5 | Q29: 3600 | R29: 1800 | S29: 4750 | T29: 1187.5 | AF29: 4750 | AG29: 4750 | AH29: 3200 | AI29: 1600 | AJ29: 5600 | AK29: 840 | AL29: 3900 | AM29: 780 | AN29: 4750 | AO29: 1187.5
I30: 7320 | J30: 7320 | K30: 2775 | L30: 971.25 | M30: 5400 | N30: 2160 | O30: 2970 | P30: 1188 | Q30: 5885 | R30: 2648.25 | S30: 7320 | T30: 3660 | AF30: 7320 | AG30: 7320 | AH30: 2775 | AI30: 971.25 | AJ30: 5400 | AK30: 2160 | AL30: 3600 | AM30: 1440 | AN30: 7320 | AO30: 3660
... I149: 2062.5 | J149: 2062.5 | K149: 5425 | L149: 2983.75 | M149: 4712.5 | N149: 942.5 | O149: 1650 | P149: 742.5 | Q149: 4725 | R149: 2362.5 | S149: 4950 | T149: 2475 | AF149: 1950 | AG149: 1950 | AH149: 5425 | AI149: 2983.75 | AJ149: 3750 | AK149: 562.5 | AL149: 3000 | AM149: 750 | AN149: 4950 | AO149: 2475
I150: 1800 | J150: 1800 | K150: 1400 | L150: 490 | M150: 1575 | N150: 630 | O150: 1662.5 | P150: 748.125 | Q150: 2625 | R150: 1312.5 | S150: 3100 | T150: 1085 | AF150: 1912.5 | AG150: 1912.5 | AH150: 1400 | AI150: 490 | AJ150: 1275 | AK150: 446.25 | AN150: 3100 | AO150: 1085
I151: 1000 | J151: 1000 | K151: 2100 | L151: 735 | M151: 2025 | N151: 506.25 | O151: 2137.5 | P151: 641.25 | Q151: 1925 | R151: 770 | S151: 3875 | T151: 775 | AF151: 1012.5 | AG151: 1012.5 | AH151: 2100 | AI151: 735 | AJ151: 1700 | AK151: 340 | AN151: 3875 | AO151: 775
I152: 750 | J152: 750 | K152: 1500 | L152: 525 | M152: 2025 | N152: 810 | O152: 2137.5 | P152: 961.875 | Q152: 1375 | R152: 412.5 | S152: 3875 | T152: 1356.25 | AF152: 787.5 | AG152: 787.5 | AH152: 1500 | AI152: 525 | AJ152: 1700 | AK152: 595 | AN152: 3875 | AO152: 1356.25
I153: 350 | J153: 350 | K153: 1750 | L153: 787.5 | M153: 1350 | N153: 472.5 | O153: 1462.5 | P153: 585 | Q153: 1200 | R153: 420 | S153: 3125 | T153: 937.5 | AF153: 300 | AG153: 300 | AH153: 1750 | AI153: 787.5 | AJ153: 1100 | AK153: 330 | AN153: 3125 | AO153: 937.5
I154: 750 | J154: 750 | K154: 1400 | L154: 420 | M154: 1250 | N154: 687.5 | O154: 1375 | P154: 825 | Q154: 2025 | R154: 810 | S154: 3162.5 | T154: 1581.25 | AF154: 687.5 | AG154: 687.5 | AH154: 1400 | AI154: 420 | AJ154: 1012.5 | AK154: 506.25 | AN154: 3162.5 | AO154: 1581.25
I155: 1000 | J155: 1000 | K155: 1750 | L155: 875 | M155: 2137.5 | N155: 427.5 | O155: 2137.5 | P155: 534.375 | Q155: 1925 | R155: 1058.75 | S155: 3875 | T155: 581.25 | AF155: 1012.5 | AG155: 1012.5 | AH155: 1750 | AI155: 875 | AJ155: 1900 | AK155: 285 | AN155: 3875 | AO155: 581.25
I156: 2000 | J156: 2000 | K156: 1625 | L156: 568.75 | M156: 1837.5 | N156: 735 | O156: 1837.5 | P156: 826.875 | Q156: 2800 | R156: 1400 | S156: 3300 | T156: 1155 | AF156: 2137.5 | AG156: 2137.5 | AH156: 1625 | AI156: 568.75 | AJ156: 1575 | AK156: 551.25 | AN156: 3300 | AO156: 1155
I157: 600 | J157: 600 | K157: 2187.5 | L157: 765.625 | M157: 1912.5 | N157: 478.125 | O157: 1912.5 | P157: 573.75 | Q157: 1575 | R157: 630 | S157: 3625 | T157: 725 | AF157: 562.5 | AG157: 562.5 | AH157: 2187.5 | AI157: 765.625 | AJ157: 1700 | AK157: 340 | AN157: 3625 | AO157: 725
I158: 600 | J158: 600 | K158: 1575 | L158: 551.25 | M158: 1912.5 | N158: 765 | O158: 2025 | P158: 911.25 | Q158: 1250 | R158: 375 | S158: 3625 | T158: 1268.75 | AF158: 612.5 | AG158: 612.5 | AH158: 1575 | AI158: 551.25 | AJ158: 1700 | AK158: 595 | AN158: 3625 | AO158: 1268.75
I159: 262.5 | J159: 262.5 | K159: 1400 | L159: 630 | M159: 1237.5 | N159: 433.125 | O159: 1350 | P159: 540 | Q159: 1125 | R159: 393.75 | S159: 2875 | T159: 862.5 | AF159: 200 | AG159: 200 | AH159: 1400 | AI159: 630 | AJ159: 1100 | AK159: 330 | AN159: 2875 | AO159: 862.5
I160: 750 | J160: 750 | K160: 1100 | L160: 330 | M160: 1000 | N160: 550 | O160: 1125 | P160: 675 | Q160: 2025 | R160: 810 | S160: 2750 | T160: 1375 | AF160: 687.5 | AG160: 687.5 | AH160: 1100 | AI160: 330 | AJ160: 900 | AK160: 450 | AN160: 2750 | AO160: 1375
...

Sheet Time Analysis-pivot table
B3: Monthly Sales Analysis
B4: Month | C4: Total Revenue (Sales) | D4: Sum of Operating Profit | J4: Sum of Total Sales | K4: Beverage Brand | T4: Sum of Total Sales | U4: Beverage Brand | AD4: Sum of Units Sold | AE4: Beverage Brand | AN4: Region | AO4: Sum of Total Sales | AP4: Average of Operating Margin | AT4: Region | AU4: Sum of Total Sales | AV4: Average of Operating Margin
B5: 1 | C5: 510750 | D5: 183334.38 | J5: Month | K5: Coca-Cola | L5: Dasani Water | M5: Diet Coke | N5: Fanta | O5: Powerade | P5: Sprite | T5: Region | U5: Coca-Cola | V5: Dasani Water | W5: Diet Coke | X5: Fanta | Y5: Powerade | Z5: Sprite | AD5: Region | AE5: Coca-Cola | AF5: Dasani Water | AG5: Diet Coke | AH5: Fanta | AI5: Powerade | AJ5: Sprite | AN5: Midwest | AO5: 1150110 | AP5: 0.37307692 | AT5: BevCo | AU5: 1291535 | AV5: 0.40625
B6: 2 | C6: 484975 | D6: 174250 | J6: 1 | K6: 110012.5 | L6: 93662.5 | M6: 94112.5 | N6: 58700 | O6: 77350 | P6: 76912.5 | T6: Midwest | U6: 344527.5 | V6: 243062.5 | W6: 178675 | X6: 103237.5 | Y6: 147175 | Z6: 133432.5 | AD6: Midwest | AE6: 811800 | AF6: 502250 | AG6: 458250 | AH6: 297250 | AI6: 313500 | AJ6: 399900 | AN6: Northeast | AO6: 1788347.5 | AP6: 0.34481838 | AT6: DreamCo | AU6: 404412.5 | AV6: 0.38333333
B7: 3 | C7: 483530 | D7: 174392 | J7: 2 | K7: 121250 | L7: 84950 | M7: 80150 | N7: 53875 | O7: 73137.5 | P7: 71612.5 | T7: Northeast | U7: 498157.5 | V7: 357712.5 | W7: 277050 | X7: 188862.5 | Y7: 242875 | Z7: 223690 | AD7: Northeast | AE7: 922450 | AF7: 610250 | AG7: 548500 | AH7: 398000 | AI7: 416000 | AJ7: 499350 | AN7: South | AO7: 1291535 | AP7: 0.40625 | AT7: FizzySip | AU7: 2584450 | AV7: 0.32916667
B8: 4 | C8: 494887.5 | D8: 177385 | J8: 3 | K8: 123667.5 | L8: 82525 | M8: 85575 | N8: 55062.5 | O8: 63075 | P8: 73625 | T8: South | U8: 248022.5 | V8: 267837.5 | W8: 231450 | X8: 165750 | Y8: 171050 | Z8: 207425 | AD8: South | AE8: 663200 | AF8: 551750 | AG8: 573000 | AH8: 396750 | AI8: 363250 | AJ8: 516850 | AN8: Southeast | AO8: 1618935 | AP8: 0.38809524 | AT8: Sodapop | AU8: 4403630 | AV8: 0.36378038
B9: 5 | C9: 673572.5 | D9: 248324.62 | J9: 4 | K9: 128250 | L9: 99987.5 | M9: 79112.5 | N9: 53962.5 | O9: 64225 | P9: 69350 | T9: Southeast | U9: 375482.5 | V9: 319662.5 | W9: 253100 | X9: 198750 | Y9: 262775 | Z9: 209165 | AD9: Southeast | AE9: 747050 | AF9: 576250 | AG9: 541250 | AH9: 458000 | AI9: 472000 | AJ9: 509900 | AN9: West | AO9: 2835100 | AP9: 0.33141026
B10: 6 | C10: 903837.5 | D10: 332843.75 | J10: 5 | K10: 166372.5 | L10: 150300 | M10: 103350 | N10: 76162.5 | O10: 85087.5 | P10: 92300 | T10: West | U10: 549700 | V10: 537562.5 | W10: 541150 | X10: 375050 | Y10: 369762.5 | Z10: 461875 | AD10: West | AE10: 988750 | AF10: 759750 | AG10: 880500 | AH10: 641250 | AI10: 556000 | AJ10: 775250
B11: 7 | C11: 1041437.5 | D11: 384724.38 | J11: 6 | K11: 193825 | L11: 213387.5 | M11: 140500 | N11: 110500 | O11: 116975 | P11: 128650
B12: 8 | C12: 945275 | D12: 349565.62 | J12: 7 | K12: 237587.5 | L12: 212825 | M12: 174187.5 | N12: 119837.5 | O12: 146750 | P12: 150250
B13: 9 | C13: 681000 | D13: 248413.75 | J13: 8 | K13: 232600 | L13: 161062.5 | M13: 179900 | N13: 107462.5 | O13: 119500 | P13: 144750
B14: 10 | C14: 623375 | D14: 226435 | J14: 9 | K14: 170737.5 | L14: 119562.5 | M14: 131187.5 | N14: 76762.5 | O14: 91400 | P14: 91350
B15: 11 | C15: 795612.5 | D15: 290547.75 | J15: 10 | K15: 146575 | L15: 125087.5 | M15: 113700 | N15: 72837.5 | O15: 83025 | P15: 82150
B16: 12 | C16: 1045775 | D16: 383415.62 | J16: 11 | K16: 150787.5 | L16: 181900 | M16: 118612.5 | N16: 111125 | O16: 127850 | P16: 105337.5
J17: 12 | K17: 234225 | L17: 200587.5 | M17: 181037.5 | N17: 135362.5 | O17: 145262.5 | P17: 149300

Sheet Summary of Data
C6: Unique Retailers | D6: Total Retailers | E6: Beverage Brand | F6: Total Beverage Brand | G6: Regions | H6: Total Regions | I6: State | J6: Total States | K6: City | L6: Total City
C7: {=_xlfn.UNIQUE(Table1[Retailer])} -> Sodapop | D7: =COUNTA(_xlfn.UNIQUE(Table1[Retailer])) -> 4 | E7: {=_xlfn.UNIQUE(Table1[Beverage Brand])} -> Coca-Cola | F7: =COUNTA(_xlfn.UNIQUE(Table1[Beverage Brand])) -> 6 | G7: {=_xlfn.UNIQUE(Table1[Region])} -> Northeast | H7: =COUNTA(_xlfn.UNIQUE(Table1[Region])) -> 5 | I7: {=_xlfn.UNIQUE(Table1[State])} -> New York | J7: =COUNTA(_xlfn.UNIQUE(Table1[State])) -> 50 | K7: {=_xlfn.UNIQUE(Table1[City])} -> New York | L7: =COUNTA(_xlfn.UNIQUE(Table1[City])) -> 52
C8: BevCo | E8: Diet Coke | G8: South | I8: Texas | K8: Houston
C9: FizzySip | E9: Sprite | G9: West | I9: California | K9: San Francisco
C10: DreamCo | E10: Fanta | G10: Midwest | I10: Illinois | K10: Los Angeles
E11: Powerade | G11: Southeast | I11: Pennsylvania | K11: Chicago
E12: Dasani Water | I12: Nevada | K12: Dallas
I13: Colorado | K13: Philadelphia
I14: Washington | K14: Las Vegas
I15: Florida | K15: Denver
I16: Minnesota | K16: Seattle
I17: Montana | K17: Miami
I18: Tennessee | K18: Minneapolis
I19: Nebraska | K19: Billings
I20: Alabama | K20: Knoxville
I21: Maine | K21: Omaha
I22: Alaska | K22: Birmingham
I23: Hawaii | K23: Portland
I24: Wyoming | K24: Anchorage
... I56: New Hampshire | K56: Boston
K57: Burlington
K58: Manchester

Sheet color themes
I5: Name | J5: Hex Code | K5: Usage
I6: Coke Red | J6: #F40009 | K6: Hero Card, primary buttons (Active), line chart data, primary icons.
I7: Pure White | J7: #FFFFFF | K7: KPI Card backgrounds, Hero text, main page container.
I8: Dashboard Gray | J8: #F8F9FA | K8: Main background color (the "canvas" behind the cards).
I9: Primary Text | J9: #1A1A1B | K9: Main headings, large numbers (KPIs), active filter labels.
I10: Secondary Text | J10: #6B7280 | K10: Subtitles, labels (e.g., "Total Annual Revenue"), axis labels.
I11: Border/Dividers | J11: #E5E7EB | K11: Navigation bar border, chart grid lines, card strokes.
I12: Accent Blue-Grey | J12: #3B82F6 | K12: Shop/Outlet icon background.
I13: Accent Teal | J13: #10B981 | K13: Market share icon background.
I15: ✍️ Typography & Font Sizes
I17: The font family used is Inter (a popular, clean sans-serif for dashboards), but you can use Segoe UI or Arial in Excel for a similar look.
I19: 1. Headings & Navigation
I21: Main Dashboard Title ("Sales Optimization"): 28px, Bold, #1A1A1B.
I22: Subtitle ("Global Markets Overview"): 14px, Regular, #6B7280.
I23: Nav Tabs ("Data", "KPIs", etc.): 14px, Semibold. (Active: White text on Red background).
I25: 2. Hero Card (Main Red Card)
I27: Main Metric Value ("$1.42B"): 42px, Bold, #FFFFFF.
I28: Metric Label ("Total Annual Revenue"): 16px, Regular, #FFFFFF (80% Opacity).
I29: Secondary Metric ("28.5%"): 24px, Bold, #FFFFFF.
I31: 3. KPI Cards (White Cards)
I33: KPI Large Number ("4.8M", "1,240"): 24px, Bold, #1A1A1B.
... I45: Status Text ("LIVE DATA CONNECTED"): 11px, Bold, Uppercase, #F40009.

Sheet format
F1: this is ok when u show the values in the tables not in the chartt
D3: Value | E3: Format code | F3: Accounting Format Code | H3: use this formul
D4: -999999999999 | E4: #,##,,,.00"B" | F4: ;(#,##,,,.00"B") | H4: TEXT(F23,LOOKUP(F23,format!$D$4:$D$10,format!$E$4:$E$10))
D5: -999999999 | E5: #,##,,.0"M" | F5: ;(#,##,,.0"M")
D6: -999999 | E6: #,#,.0"K" | F6: ;(#,#,.0"K")
D7: -999 | E7: #,##0 | F7: #,##0;(#,##0)
D8: 1000 | E8: #,#,.0"K" | F8: #,#,.0"K"
D9: 1000000 | E9: #,##,,.0"M" | F9: #,##,,.0"M"
D10: 1000000000 | E10: #,##,,,.0"B" | F10: #,##,,,.0"B"

Sheet Sales Analysis
AE89: 0

Sheet Sales Analysis -2

Sheet Time Analysis

Sheet Heatmap
D5: Month | E5: Midwest | F5: Northeast | G5: South | H5: Southeast | I5: West | K5: Month | L5: BevCo | M5: DreamCo | N5: FizzySip | O5: Sodapop
D6: ='Sales & Profitability Analysis'!BE7 -> Jan | E6: ='Sales & Profitability Analysis'!BF7 -> 80087.5 | F6: ='Sales & Profitability Analysis'!BG7 -> 115737.5 | G6: ='Sales & Profitability Analysis'!BH7 -> 70662.5 | H6: ='Sales & Profitability Analysis'!BI7 -> 104750 | I6: ='Sales & Profitability Analysis'!BJ7 -> 139512.5 | K6: ='Sales & Profitability Analysis'!BM7 -> Jan | L6: ='Sales & Profitability Analysis'!BN7 -> 70662.5 | M6: ='Sales & Profitability Analysis'!BO7 -> 27787.5 | N6: ='Sales & Profitability Analysis'!BP7 -> 122637.5 | O6: ='Sales & Profitability Analysis'!BQ7 -> 289662.5
D7: ='Sales & Profitability Analysis'!BE8 -> Feb | E7: ='Sales & Profitability Analysis'!BF8 -> 73762.5 | F7: ='Sales & Profitability Analysis'!BG8 -> 112650 | G7: ='Sales & Profitability Analysis'!BH8 -> 66475 | H7: ='Sales & Profitability Analysis'!BI8 -> 99500 | I7: ='Sales & Profitability Analysis'!BJ8 -> 132587.5 | K7: ='Sales & Profitability Analysis'!BM8 -> Feb | L7: ='Sales & Profitability Analysis'!BN8 -> 66475 | M7: ='Sales & Profitability Analysis'!BO8 -> 26287.5 | N7: ='Sales & Profitability Analysis'!BP8 -> 116462.5 | O7: ='Sales & Profitability Analysis'!BQ8 -> 275750
D8: ='Sales & Profitability Analysis'!BE9 -> Mar | E8: ='Sales & Profitability Analysis'!BF9 -> 68072.5 | F8: ='Sales & Profitability Analysis'!BG9 -> 104985 | G8: ='Sales & Profitability Analysis'!BH9 -> 65845 | H8: ='Sales & Profitability Analysis'!BI9 -> 86102.5 | I8: ='Sales & Profitability Analysis'!BJ9 -> 158525 | K8: ='Sales & Profitability Analysis'!BM9 -> Mar | L8: ='Sales & Profitability Analysis'!BN9 -> 65845 | M8: ='Sales & Profitability Analysis'!BO9 -> 26162.5 | N8: ='Sales & Profitability Analysis'!BP9 -> 142462.5 | O8: ='Sales & Profitability Analysis'!BQ9 -> 249060
D9: ='Sales & Profitability Analysis'!BE10 -> Apr | E9: ='Sales & Profitability Analysis'!BF10 -> 65762.5 | F9: ='Sales & Profitability Analysis'!BG10 -> 101175 | G9: ='Sales & Profitability Analysis'!BH10 -> 60662.5 | H9: ='Sales & Profitability Analysis'!BI10 -> 88525 | I9: ='Sales & Profitability Analysis'!BJ10 -> 178762.5 | K9: ='Sales & Profitability Analysis'!BM10 -> Apr | L9: ='Sales & Profitability Analysis'!BN10 -> 60662.5 | M9: ='Sales & Profitability Analysis'!BO10 -> 28537.5 | N9: ='Sales & Profitability Analysis'!BP10 -> 160650 | O9: ='Sales & Profitability Analysis'!BQ10 -> 245037.5
D10: ='Sales & Profitability Analysis'!BE11 -> May | E10: ='Sales & Profitability Analysis'!BF11 -> 97392.5 | F10: ='Sales & Profitability Analysis'!BG11 -> 154247.5 | G10: ='Sales & Profitability Analysis'!BH11 -> 89965 | H10: ='Sales & Profitability Analysis'!BI11 -> 133555 | I10: ='Sales & Profitability Analysis'!BJ11 -> 198412.5 | K10: ='Sales & Profitability Analysis'!BM11 -> May | L10: ='Sales & Profitability Analysis'!BN11 -> 89965 | M10: ='Sales & Profitability Analysis'!BO11 -> 29725 | N10: ='Sales & Profitability Analysis'!BP11 -> 179525 | O10: ='Sales & Profitability Analysis'!BQ11 -> 374357.5
D11: ='Sales & Profitability Analysis'!BE12 -> Jun | E11: ='Sales & Profitability Analysis'!BF12 -> 101637.5 | F11: ='Sales & Profitability Analysis'!BG12 -> 176437.5 | G11: ='Sales & Profitability Analysis'!BH12 -> 134537.5 | H11: ='Sales & Profitability Analysis'!BI12 -> 162687.5 | I11: ='Sales & Profitability Analysis'!BJ12 -> 328537.5 | K11: ='Sales & Profitability Analysis'!BM12 -> Jun | L11: ='Sales & Profitability Analysis'!BN12 -> 134537.5 | M11: ='Sales & Profitability Analysis'!BO12 -> 36250 | N11: ='Sales & Profitability Analysis'!BP12 -> 306475 | O11: ='Sales & Profitability Analysis'!BQ12 -> 426575
D12: ='Sales & Profitability Analysis'!BE13 -> Jul | E12: ='Sales & Profitability Analysis'!BF13 -> 131387.5 | F12: ='Sales & Profitability Analysis'!BG13 -> 187900 | G12: ='Sales & Profitability Analysis'!BH13 -> 157912.5 | H12: ='Sales & Profitability Analysis'!BI13 -> 191425 | I12: ='Sales & Profitability Analysis'!BJ13 -> 372812.5 | K12: ='Sales & Profitability Analysis'!BM13 -> Jul | L12: ='Sales & Profitability Analysis'!BN13 -> 157912.5 | M12: ='Sales & Profitability Analysis'!BO13 -> 37962.5 | N12: ='Sales & Profitability Analysis'!BP13 -> 349812.5 | O12: ='Sales & Profitability Analysis'!BQ13 -> 495750
D13: ='Sales & Profitability Analysis'!BE14 -> Aug | E13: ='Sales & Profitability Analysis'!BF14 -> 120312.5 | F13: ='Sales & Profitability Analysis'!BG14 -> 173362.5 | G13: ='Sales & Profitability Analysis'!BH14 -> 152275 | H13: ='Sales & Profitability Analysis'!BI14 -> 170700 | I13: ='Sales & Profitability Analysis'!BJ14 -> 328625 | K13: ='Sales & Profitability Analysis'!BM14 -> Aug | L13: ='Sales & Profitability Analysis'!BN14 -> 152275 | M13: ='Sales & Profitability Analysis'!BO14 -> 40075 | N13: ='Sales & Profitability Analysis'!BP14 -> 304175 | O13: ='Sales & Profitability Analysis'!BQ14 -> 448750
D14: ='Sales & Profitability Analysis'!BE15 -> Sep | E14: ='Sales & Profitability Analysis'!BF15 -> 81087.5 | F14: ='Sales & Profitability Analysis'!BG15 -> 142037.5 | G14: ='Sales & Profitability Analysis'!BH15 -> 117225 | H14: ='Sales & Profitability Analysis'!BI15 -> 124537.5 | I14: ='Sales & Profitability Analysis'!BJ15 -> 216112.5 | K14: ='Sales & Profitability Analysis'!BM15 -> Sep | L14: ='Sales & Profitability Analysis'!BN15 -> 117225 | M14: ='Sales & Profitability Analysis'!BO15 -> 38550 | N14: ='Sales & Profitability Analysis'!BP15 -> 191987.5 | O14: ='Sales & Profitability Analysis'!BQ15 -> 333237.5
D15: ='Sales & Profitability Analysis'!BE16 -> Oct | E15: ='Sales & Profitability Analysis'!BF16 -> 82800 | F15: ='Sales & Profitability Analysis'!BG16 -> 143887.5 | G15: ='Sales & Profitability Analysis'!BH16 -> 81687.5 | H15: ='Sales & Profitability Analysis'!BI16 -> 119525 | I15: ='Sales & Profitability Analysis'!BJ16 -> 195475 | K15: ='Sales & Profitability Analysis'!BM16 -> Oct | L15: ='Sales & Profitability Analysis'!BN16 -> 81687.5 | M15: ='Sales & Profitability Analysis'!BO16 -> 35637.5 | N15: ='Sales & Profitability Analysis'!BP16 -> 172875 | O15: ='Sales & Profitability Analysis'!BQ16 -> 333175
D16: ='Sales & Profitability Analysis'!BE17 -> Nov | E16: ='Sales & Profitability Analysis'!BF17 -> 102420 | F16: ='Sales & Profitability Analysis'!BG17 -> 173315 | G16: ='Sales & Profitability Analysis'!BH17 -> 118800 | H16: ='Sales & Profitability Analysis'!BI17 -> 146152.5 | I16: ='Sales & Profitability Analysis'!BJ17 -> 254925 | K16: ='Sales & Profitability Analysis'!BM17 -> Nov | L16: ='Sales & Profitability Analysis'!BN17 -> 118800 | M16: ='Sales & Profitability Analysis'!BO17 -> 36637.5 | N16: ='Sales & Profitability Analysis'!BP17 -> 231487.5 | O16: ='Sales & Profitability Analysis'!BQ17 -> 408687.5
D17: ='Sales & Profitability Analysis'!BE18 -> Dec | E17: ='Sales & Profitability Analysis'!BF18 -> 145387.5 | F17: ='Sales & Profitability Analysis'!BG18 -> 202612.5 | G17: ='Sales & Profitability Analysis'!BH18 -> 175487.5 | H17: ='Sales & Profitability Analysis'!BI18 -> 191475 | I17: ='Sales & Profitability Analysis'!BJ18 -> 330812.5 | K17: ='Sales & Profitability Analysis'!BM18 -> Dec | L17: ='Sales & Profitability Analysis'!BN18 -> 175487.5 | M17: ='Sales & Profitability Analysis'!BO18 -> 40800 | N17: ='Sales & Profitability Analysis'!BP18 -> 305900 | O17: ='Sales & Profitability Analysis'!BQ18 -> 523587.5
